[2025-08-29T19:03:39.078+0000] {taskinstance.py:1171} INFO - Dependencies all met for <TaskInstance: etl_P2M3_muhammad_al_ghifari.preprocess_data scheduled__2025-08-02T02:10:00+00:00 [queued]>
[2025-08-29T19:03:39.277+0000] {taskinstance.py:1171} INFO - Dependencies all met for <TaskInstance: etl_P2M3_muhammad_al_ghifari.preprocess_data scheduled__2025-08-02T02:10:00+00:00 [queued]>
[2025-08-29T19:03:39.281+0000] {taskinstance.py:1368} INFO - 
--------------------------------------------------------------------------------
[2025-08-29T19:03:39.293+0000] {taskinstance.py:1369} INFO - Starting attempt 1 of 1
[2025-08-29T19:03:39.294+0000] {taskinstance.py:1370} INFO - 
--------------------------------------------------------------------------------
[2025-08-29T19:03:40.724+0000] {taskinstance.py:1389} INFO - Executing <Task(_PythonDecoratedOperator): preprocess_data> on 2025-08-02 02:10:00+00:00
[2025-08-29T19:03:40.780+0000] {standard_task_runner.py:52} INFO - Started process 279 to run task
[2025-08-29T19:03:40.823+0000] {standard_task_runner.py:79} INFO - Running: ['***', 'tasks', 'run', 'etl_P2M3_muhammad_al_ghifari', 'preprocess_data', 'scheduled__2025-08-02T02:10:00+00:00', '--job-id', '271', '--raw', '--subdir', 'DAGS_FOLDER/P2M3_muhammad_al_ghifari_DAG.py', '--cfg-path', '/tmp/tmp6l6_oqn0', '--error-file', '/tmp/tmpc6is07gd']
[2025-08-29T19:03:40.834+0000] {standard_task_runner.py:80} INFO - Job 271: Subtask preprocess_data
[2025-08-29T19:03:41.918+0000] {task_command.py:371} INFO - Running <TaskInstance: etl_P2M3_muhammad_al_ghifari.preprocess_data scheduled__2025-08-02T02:10:00+00:00 [running]> on host dfc6b3a208a1
[2025-08-29T19:03:43.251+0000] {local_task_job.py:84} ERROR - Received SIGTERM. Terminating subprocesses
[2025-08-29T19:03:43.337+0000] {process_utils.py:129} INFO - Sending Signals.SIGTERM to group 279. PIDs of all processes in the group: [279]
[2025-08-29T19:03:43.356+0000] {process_utils.py:80} INFO - Sending the signal Signals.SIGTERM to group 279
[2025-08-29T19:03:43.738+0000] {taskinstance.py:1553} ERROR - Received SIGTERM. Terminating subprocesses.
[2025-08-29T19:03:48.639+0000] {taskinstance.py:1902} ERROR - Task failed with exception
Traceback (most recent call last):
  File "/home/airflow/.local/lib/python3.7/site-packages/airflow/models/taskinstance.py", line 1463, in _run_raw_task
    self._execute_task_with_callbacks(context, test_mode)
  File "/home/airflow/.local/lib/python3.7/site-packages/airflow/models/taskinstance.py", line 1570, in _execute_task_with_callbacks
    RenderedTaskInstanceFields.write(rtif)
  File "/home/airflow/.local/lib/python3.7/site-packages/airflow/utils/session.py", line 71, in wrapper
    return func(*args, session=session, **kwargs)
  File "/home/airflow/.local/lib/python3.7/site-packages/airflow/models/renderedtifields.py", line 169, in write
    session.merge(self)
  File "/home/airflow/.local/lib/python3.7/site-packages/sqlalchemy/orm/session.py", line 2961, in merge
    _resolve_conflict_map=_resolve_conflict_map,
  File "/home/airflow/.local/lib/python3.7/site-packages/sqlalchemy/orm/session.py", line 3039, in _merge
    options=options,
  File "/home/airflow/.local/lib/python3.7/site-packages/sqlalchemy/orm/session.py", line 2775, in get
    identity_token=identity_token,
  File "/home/airflow/.local/lib/python3.7/site-packages/sqlalchemy/orm/session.py", line 2878, in _get_impl
    load_options=load_options,
  File "/home/airflow/.local/lib/python3.7/site-packages/sqlalchemy/orm/loading.py", line 534, in load_on_pk_identity
    bind_arguments=bind_arguments,
  File "/home/airflow/.local/lib/python3.7/site-packages/sqlalchemy/orm/session.py", line 1688, in execute
    conn = self._connection_for_bind(bind)
  File "/home/airflow/.local/lib/python3.7/site-packages/sqlalchemy/orm/session.py", line 1530, in _connection_for_bind
    engine, execution_options
  File "/home/airflow/.local/lib/python3.7/site-packages/sqlalchemy/orm/session.py", line 747, in _connection_for_bind
    conn = bind.connect()
  File "/home/airflow/.local/lib/python3.7/site-packages/sqlalchemy/engine/base.py", line 3197, in connect
    return self._connection_cls(self, close_with_result=close_with_result)
  File "/home/airflow/.local/lib/python3.7/site-packages/sqlalchemy/engine/base.py", line 96, in __init__
    else engine.raw_connection()
  File "/home/airflow/.local/lib/python3.7/site-packages/sqlalchemy/engine/base.py", line 3276, in raw_connection
    return self._wrap_pool_connect(self.pool.connect, _connection)
  File "/home/airflow/.local/lib/python3.7/site-packages/sqlalchemy/engine/base.py", line 3243, in _wrap_pool_connect
    return fn()
  File "/home/airflow/.local/lib/python3.7/site-packages/sqlalchemy/pool/base.py", line 310, in connect
    return _ConnectionFairy._checkout(self)
  File "/home/airflow/.local/lib/python3.7/site-packages/sqlalchemy/pool/base.py", line 868, in _checkout
    fairy = _ConnectionRecord.checkout(pool)
  File "/home/airflow/.local/lib/python3.7/site-packages/sqlalchemy/pool/base.py", line 476, in checkout
    rec = pool._do_get()
  File "/home/airflow/.local/lib/python3.7/site-packages/sqlalchemy/pool/impl.py", line 256, in _do_get
    return self._create_connection()
  File "/home/airflow/.local/lib/python3.7/site-packages/sqlalchemy/pool/base.py", line 256, in _create_connection
    return _ConnectionRecord(self)
  File "/home/airflow/.local/lib/python3.7/site-packages/sqlalchemy/pool/base.py", line 371, in __init__
    self.__connect()
  File "/home/airflow/.local/lib/python3.7/site-packages/sqlalchemy/pool/base.py", line 666, in __connect
    pool.logger.debug("Error on connect(): %s", e)
  File "/home/airflow/.local/lib/python3.7/site-packages/sqlalchemy/util/langhelpers.py", line 72, in __exit__
    with_traceback=exc_tb,
  File "/home/airflow/.local/lib/python3.7/site-packages/sqlalchemy/util/compat.py", line 207, in raise_
    raise exception
  File "/home/airflow/.local/lib/python3.7/site-packages/sqlalchemy/pool/base.py", line 661, in __connect
    self.dbapi_connection = connection = pool._invoke_creator(self)
  File "/home/airflow/.local/lib/python3.7/site-packages/sqlalchemy/engine/create.py", line 590, in connect
    return dialect.connect(*cargs, **cparams)
  File "/home/airflow/.local/lib/python3.7/site-packages/sqlalchemy/engine/default.py", line 584, in connect
    return self.dbapi.connect(*cargs, **cparams)
  File "/home/airflow/.local/lib/python3.7/site-packages/psycopg2/__init__.py", line 122, in connect
    conn = _connect(dsn, connection_factory=connection_factory, **kwasync)
  File "/home/airflow/.local/lib/python3.7/site-packages/airflow/models/taskinstance.py", line 1555, in signal_handler
    raise AirflowException("Task received SIGTERM signal")
airflow.exceptions.AirflowException: Task received SIGTERM signal
[2025-08-29T19:03:48.811+0000] {taskinstance.py:1412} INFO - Marking task as FAILED. dag_id=etl_P2M3_muhammad_al_ghifari, task_id=preprocess_data, execution_date=20250802T021000, start_date=20250829T190339, end_date=20250829T190348
[2025-08-29T19:03:48.943+0000] {standard_task_runner.py:97} ERROR - Failed to execute job 271 for task preprocess_data (Task received SIGTERM signal; 279)
[2025-08-29T19:03:49.036+0000] {process_utils.py:75} INFO - Process psutil.Process(pid=279, status='terminated', exitcode=1, started='19:03:40') (279) terminated with exit code 1
[2025-08-29T19:03:49.075+0000] {local_task_job.py:156} INFO - Task exited with return code 143
[2025-08-29T19:03:50.167+0000] {local_task_job.py:279} INFO - 0 downstream tasks scheduled from follow-on schedule check
