[2025-08-29T18:50:30.320+0000] {taskinstance.py:1171} INFO - Dependencies all met for <TaskInstance: etl_P2M3_muhammad_al_ghifari.extract scheduled__2025-07-19T02:10:00+00:00 [queued]>
[2025-08-29T18:50:31.539+0000] {taskinstance.py:1171} INFO - Dependencies all met for <TaskInstance: etl_P2M3_muhammad_al_ghifari.extract scheduled__2025-07-19T02:10:00+00:00 [queued]>
[2025-08-29T18:50:31.775+0000] {taskinstance.py:1368} INFO - 
--------------------------------------------------------------------------------
[2025-08-29T18:50:31.778+0000] {taskinstance.py:1369} INFO - Starting attempt 1 of 1
[2025-08-29T18:50:31.788+0000] {taskinstance.py:1370} INFO - 
--------------------------------------------------------------------------------
[2025-08-29T18:50:32.885+0000] {taskinstance.py:1389} INFO - Executing <Task(_PythonDecoratedOperator): extract> on 2025-07-19 02:10:00+00:00
[2025-08-29T18:50:34.462+0000] {standard_task_runner.py:52} INFO - Started process 444 to run task
[2025-08-29T18:50:36.004+0000] {standard_task_runner.py:79} INFO - Running: ['***', 'tasks', 'run', 'etl_P2M3_muhammad_al_ghifari', 'extract', 'scheduled__2025-07-19T02:10:00+00:00', '--job-id', '243', '--raw', '--subdir', 'DAGS_FOLDER/P2M3_muhammad_al_ghifari_DAG.py', '--cfg-path', '/tmp/tmpnn8qdi3a', '--error-file', '/tmp/tmpwntcjt4a']
[2025-08-29T18:50:36.097+0000] {standard_task_runner.py:80} INFO - Job 243: Subtask extract
[2025-08-29T18:50:44.643+0000] {task_command.py:371} INFO - Running <TaskInstance: etl_P2M3_muhammad_al_ghifari.extract scheduled__2025-07-19T02:10:00+00:00 [running]> on host b40c5a90b1e4
[2025-08-29T18:51:12.426+0000] {local_task_job.py:84} ERROR - Received SIGTERM. Terminating subprocesses
[2025-08-29T18:51:13.403+0000] {process_utils.py:129} INFO - Sending Signals.SIGTERM to group 444. PIDs of all processes in the group: [444]
[2025-08-29T18:51:13.467+0000] {process_utils.py:80} INFO - Sending the signal Signals.SIGTERM to group 444
[2025-08-29T18:51:13.624+0000] {taskinstance.py:1553} ERROR - Received SIGTERM. Terminating subprocesses.
[2025-08-29T18:51:14.864+0000] {taskinstance.py:1902} ERROR - Task failed with exception
Traceback (most recent call last):
  File "/home/airflow/.local/lib/python3.7/site-packages/airflow/models/taskinstance.py", line 1463, in _run_raw_task
    self._execute_task_with_callbacks(context, test_mode)
  File "/home/airflow/.local/lib/python3.7/site-packages/airflow/models/taskinstance.py", line 1571, in _execute_task_with_callbacks
    RenderedTaskInstanceFields.delete_old_records(self.task_id, self.dag_id)
  File "/home/airflow/.local/lib/python3.7/site-packages/airflow/utils/session.py", line 71, in wrapper
    return func(*args, session=session, **kwargs)
  File "/home/airflow/.local/lib/python3.7/site-packages/airflow/models/renderedtifields.py", line 213, in delete_old_records
    ).delete(synchronize_session=False)
  File "/home/airflow/.local/lib/python3.7/site-packages/sqlalchemy/orm/query.py", line 3194, in delete
    execution_options={"synchronize_session": synchronize_session},
  File "/home/airflow/.local/lib/python3.7/site-packages/sqlalchemy/orm/session.py", line 1689, in execute
    result = conn._execute_20(statement, params or {}, execution_options)
  File "/home/airflow/.local/lib/python3.7/site-packages/sqlalchemy/engine/base.py", line 1614, in _execute_20
    return meth(self, args_10style, kwargs_10style, execution_options)
  File "/home/airflow/.local/lib/python3.7/site-packages/sqlalchemy/sql/elements.py", line 326, in _execute_on_connection
    self, multiparams, params, execution_options
  File "/home/airflow/.local/lib/python3.7/site-packages/sqlalchemy/engine/base.py", line 1491, in _execute_clauseelement
    cache_hit=cache_hit,
  File "/home/airflow/.local/lib/python3.7/site-packages/sqlalchemy/engine/base.py", line 1846, in _execute_context
    e, statement, parameters, cursor, context
  File "/home/airflow/.local/lib/python3.7/site-packages/sqlalchemy/engine/base.py", line 2030, in _handle_dbapi_exception
    util.raise_(exc_info[1], with_traceback=exc_info[2])
  File "/home/airflow/.local/lib/python3.7/site-packages/sqlalchemy/util/compat.py", line 207, in raise_
    raise exception
  File "/home/airflow/.local/lib/python3.7/site-packages/sqlalchemy/engine/base.py", line 1803, in _execute_context
    cursor, statement, parameters, context
  File "/home/airflow/.local/lib/python3.7/site-packages/sqlalchemy/engine/default.py", line 719, in do_execute
    cursor.execute(statement, parameters)
  File "/usr/local/lib/python3.7/encodings/utf_8.py", line 15, in decode
    def decode(input, errors='strict'):
  File "/home/airflow/.local/lib/python3.7/site-packages/airflow/models/taskinstance.py", line 1555, in signal_handler
    raise AirflowException("Task received SIGTERM signal")
airflow.exceptions.AirflowException: Task received SIGTERM signal
[2025-08-29T18:51:15.304+0000] {taskinstance.py:1412} INFO - Marking task as FAILED. dag_id=etl_P2M3_muhammad_al_ghifari, task_id=extract, execution_date=20250719T021000, start_date=20250829T185030, end_date=20250829T185115
[2025-08-29T18:51:16.035+0000] {standard_task_runner.py:97} ERROR - Failed to execute job 243 for task extract (Task received SIGTERM signal; 444)
[2025-08-29T18:51:16.167+0000] {process_utils.py:75} INFO - Process psutil.Process(pid=444, status='terminated', exitcode=1, started='18:50:34') (444) terminated with exit code 1
[2025-08-29T18:51:16.274+0000] {local_task_job.py:156} INFO - Task exited with return code 143
[2025-08-29T18:51:17.364+0000] {local_task_job.py:279} INFO - 0 downstream tasks scheduled from follow-on schedule check
