[2025-08-29T18:50:30.302+0000] {taskinstance.py:1171} INFO - Dependencies all met for <TaskInstance: etl_P2M3_muhammad_al_ghifari.preprocess_data scheduled__2025-06-28T02:10:00+00:00 [queued]>
[2025-08-29T18:50:30.589+0000] {taskinstance.py:1171} INFO - Dependencies all met for <TaskInstance: etl_P2M3_muhammad_al_ghifari.preprocess_data scheduled__2025-06-28T02:10:00+00:00 [queued]>
[2025-08-29T18:50:30.596+0000] {taskinstance.py:1368} INFO - 
--------------------------------------------------------------------------------
[2025-08-29T18:50:30.597+0000] {taskinstance.py:1369} INFO - Starting attempt 1 of 1
[2025-08-29T18:50:30.601+0000] {taskinstance.py:1370} INFO - 
--------------------------------------------------------------------------------
[2025-08-29T18:50:30.795+0000] {taskinstance.py:1389} INFO - Executing <Task(_PythonDecoratedOperator): preprocess_data> on 2025-06-28 02:10:00+00:00
[2025-08-29T18:50:31.051+0000] {standard_task_runner.py:52} INFO - Started process 440 to run task
[2025-08-29T18:50:31.331+0000] {standard_task_runner.py:79} INFO - Running: ['***', 'tasks', 'run', 'etl_P2M3_muhammad_al_ghifari', 'preprocess_data', 'scheduled__2025-06-28T02:10:00+00:00', '--job-id', '244', '--raw', '--subdir', 'DAGS_FOLDER/P2M3_muhammad_al_ghifari_DAG.py', '--cfg-path', '/tmp/tmphf4f5rst', '--error-file', '/tmp/tmp9k6spqoe']
[2025-08-29T18:50:31.381+0000] {standard_task_runner.py:80} INFO - Job 244: Subtask preprocess_data
[2025-08-29T18:50:36.735+0000] {task_command.py:371} INFO - Running <TaskInstance: etl_P2M3_muhammad_al_ghifari.preprocess_data scheduled__2025-06-28T02:10:00+00:00 [running]> on host b40c5a90b1e4
[2025-08-29T18:50:52.166+0000] {taskinstance.py:1583} INFO - Exporting the following env vars:
AIRFLOW_CTX_DAG_OWNER=Muhammad Al Ghifari
AIRFLOW_CTX_DAG_ID=etl_P2M3_muhammad_al_ghifari
AIRFLOW_CTX_TASK_ID=preprocess_data
AIRFLOW_CTX_EXECUTION_DATE=2025-06-28T02:10:00+00:00
AIRFLOW_CTX_TRY_NUMBER=1
AIRFLOW_CTX_DAG_RUN_ID=scheduled__2025-06-28T02:10:00+00:00
[2025-08-29T18:51:06.990+0000] {logging_mixin.py:115} INFO - Preprocessed data is Success
[2025-08-29T18:51:10.087+0000] {logging_mixin.py:115} INFO -    unnamed_0 shipment_id  ... distance_miles transit_days
0          0     SH10000  ...            291            2
1          1     SH10001  ...           1225            3
2          2     SH10002  ...            220            2
3          3     SH10003  ...           1156            9
4          4     SH10004  ...           1017            3

[5 rows x 12 columns]
[2025-08-29T18:51:12.983+0000] {local_task_job.py:84} ERROR - Received SIGTERM. Terminating subprocesses
[2025-08-29T18:51:13.907+0000] {process_utils.py:129} INFO - Sending Signals.SIGTERM to group 440. PIDs of all processes in the group: [440]
[2025-08-29T18:51:14.013+0000] {process_utils.py:80} INFO - Sending the signal Signals.SIGTERM to group 440
[2025-08-29T18:51:14.206+0000] {taskinstance.py:1553} ERROR - Received SIGTERM. Terminating subprocesses.
[2025-08-29T18:51:15.075+0000] {taskinstance.py:1902} ERROR - Task failed with exception
Traceback (most recent call last):
  File "/home/airflow/.local/lib/python3.7/site-packages/airflow/decorators/base.py", line 179, in execute
    return_value = super().execute(context)
  File "/home/airflow/.local/lib/python3.7/site-packages/airflow/operators/python.py", line 171, in execute
    return_value = self.execute_callable()
  File "/home/airflow/.local/lib/python3.7/site-packages/airflow/operators/python.py", line 189, in execute_callable
    return self.python_callable(*self.op_args, **self.op_kwargs)
  File "/opt/airflow/dags/P2M3_muhammad_al_ghifari_DAG.py", line 162, in preprocess_data
    df.to_csv('/opt/airflow/dags/P2M3_muhammad_al_ghifari_data_cleaned.csv', index=False)
  File "/home/airflow/.local/lib/python3.7/site-packages/pandas/core/generic.py", line 3482, in to_csv
    storage_options=storage_options,
  File "/home/airflow/.local/lib/python3.7/site-packages/pandas/io/formats/format.py", line 1105, in to_csv
    csv_formatter.save()
  File "/home/airflow/.local/lib/python3.7/site-packages/pandas/io/formats/csvs.py", line 257, in save
    self._save()
  File "/home/airflow/.local/lib/python3.7/site-packages/pandas/io/formats/csvs.py", line 262, in _save
    self._save_body()
  File "/home/airflow/.local/lib/python3.7/site-packages/pandas/io/formats/csvs.py", line 300, in _save_body
    self._save_chunk(start_i, end_i)
  File "/home/airflow/.local/lib/python3.7/site-packages/pandas/io/formats/csvs.py", line 305, in _save_chunk
    df = self.obj.iloc[slicer]
  File "/home/airflow/.local/lib/python3.7/site-packages/pandas/core/indexing.py", line 931, in __getitem__
    return self._getitem_axis(maybe_callable, axis=axis)
  File "/home/airflow/.local/lib/python3.7/site-packages/pandas/core/indexing.py", line 1543, in _getitem_axis
    return self._get_slice_axis(key, axis=axis)
  File "/home/airflow/.local/lib/python3.7/site-packages/pandas/core/indexing.py", line 1579, in _get_slice_axis
    return self.obj._slice(slice_obj, axis=axis)
  File "/home/airflow/.local/lib/python3.7/site-packages/pandas/core/generic.py", line 3829, in _slice
    result = result.__finalize__(self)
  File "/home/airflow/.local/lib/python3.7/site-packages/pandas/core/generic.py", line 5456, in __finalize__
    for name in other.attrs:
  File "/home/airflow/.local/lib/python3.7/site-packages/pandas/core/generic.py", line 324, in attrs
    @property
  File "/home/airflow/.local/lib/python3.7/site-packages/airflow/models/taskinstance.py", line 1555, in signal_handler
    raise AirflowException("Task received SIGTERM signal")
airflow.exceptions.AirflowException: Task received SIGTERM signal
[2025-08-29T18:51:15.845+0000] {taskinstance.py:1412} INFO - Marking task as FAILED. dag_id=etl_P2M3_muhammad_al_ghifari, task_id=preprocess_data, execution_date=20250628T021000, start_date=20250829T185030, end_date=20250829T185115
[2025-08-29T18:51:16.164+0000] {standard_task_runner.py:97} ERROR - Failed to execute job 244 for task preprocess_data (Task received SIGTERM signal; 440)
[2025-08-29T18:51:16.272+0000] {process_utils.py:75} INFO - Process psutil.Process(pid=440, status='terminated', exitcode=1, started='18:50:30') (440) terminated with exit code 1
[2025-08-29T18:51:16.334+0000] {local_task_job.py:156} INFO - Task exited with return code 143
[2025-08-29T18:51:17.474+0000] {local_task_job.py:279} INFO - 0 downstream tasks scheduled from follow-on schedule check
