[2025-08-29T18:50:30.128+0000] {taskinstance.py:1171} INFO - Dependencies all met for <TaskInstance: etl_P2M3_muhammad_al_ghifari.extract scheduled__2025-07-19T02:20:00+00:00 [queued]>
[2025-08-29T18:50:31.418+0000] {taskinstance.py:1171} INFO - Dependencies all met for <TaskInstance: etl_P2M3_muhammad_al_ghifari.extract scheduled__2025-07-19T02:20:00+00:00 [queued]>
[2025-08-29T18:50:31.897+0000] {taskinstance.py:1368} INFO - 
--------------------------------------------------------------------------------
[2025-08-29T18:50:31.903+0000] {taskinstance.py:1369} INFO - Starting attempt 1 of 1
[2025-08-29T18:50:31.919+0000] {taskinstance.py:1370} INFO - 
--------------------------------------------------------------------------------
[2025-08-29T18:50:34.546+0000] {taskinstance.py:1389} INFO - Executing <Task(_PythonDecoratedOperator): extract> on 2025-07-19 02:20:00+00:00
[2025-08-29T18:50:35.319+0000] {standard_task_runner.py:52} INFO - Started process 446 to run task
[2025-08-29T18:50:36.052+0000] {standard_task_runner.py:79} INFO - Running: ['***', 'tasks', 'run', 'etl_P2M3_muhammad_al_ghifari', 'extract', 'scheduled__2025-07-19T02:20:00+00:00', '--job-id', '246', '--raw', '--subdir', 'DAGS_FOLDER/P2M3_muhammad_al_ghifari_DAG.py', '--cfg-path', '/tmp/tmp9b5yf40q', '--error-file', '/tmp/tmp4i3uhlpu']
[2025-08-29T18:50:36.153+0000] {standard_task_runner.py:80} INFO - Job 246: Subtask extract
[2025-08-29T18:50:46.882+0000] {task_command.py:371} INFO - Running <TaskInstance: etl_P2M3_muhammad_al_ghifari.extract scheduled__2025-07-19T02:20:00+00:00 [running]> on host b40c5a90b1e4
[2025-08-29T18:51:10.117+0000] {taskinstance.py:1583} INFO - Exporting the following env vars:
AIRFLOW_CTX_DAG_OWNER=Muhammad Al Ghifari
AIRFLOW_CTX_DAG_ID=etl_P2M3_muhammad_al_ghifari
AIRFLOW_CTX_TASK_ID=extract
AIRFLOW_CTX_EXECUTION_DATE=2025-07-19T02:20:00+00:00
AIRFLOW_CTX_TRY_NUMBER=1
AIRFLOW_CTX_DAG_RUN_ID=scheduled__2025-07-19T02:20:00+00:00
[2025-08-29T18:51:13.336+0000] {local_task_job.py:84} ERROR - Received SIGTERM. Terminating subprocesses
[2025-08-29T18:51:14.501+0000] {process_utils.py:129} INFO - Sending Signals.SIGTERM to group 446. PIDs of all processes in the group: [446]
[2025-08-29T18:51:14.518+0000] {process_utils.py:80} INFO - Sending the signal Signals.SIGTERM to group 446
[2025-08-29T18:51:14.552+0000] {taskinstance.py:1553} ERROR - Received SIGTERM. Terminating subprocesses.
[2025-08-29T18:51:15.088+0000] {taskinstance.py:1902} ERROR - Task failed with exception
Traceback (most recent call last):
  File "/home/airflow/.local/lib/python3.7/site-packages/airflow/decorators/base.py", line 179, in execute
    return_value = super().execute(context)
  File "/home/airflow/.local/lib/python3.7/site-packages/airflow/operators/python.py", line 171, in execute
    return_value = self.execute_callable()
  File "/home/airflow/.local/lib/python3.7/site-packages/airflow/operators/python.py", line 189, in execute_callable
    return self.python_callable(*self.op_args, **self.op_kwargs)
  File "/opt/airflow/dags/P2M3_muhammad_al_ghifari_DAG.py", line 78, in extract
    conn = engine.connect()
  File "/home/airflow/.local/lib/python3.7/site-packages/sqlalchemy/engine/base.py", line 3197, in connect
    return self._connection_cls(self, close_with_result=close_with_result)
  File "/home/airflow/.local/lib/python3.7/site-packages/sqlalchemy/engine/base.py", line 96, in __init__
    else engine.raw_connection()
  File "/home/airflow/.local/lib/python3.7/site-packages/sqlalchemy/engine/base.py", line 3276, in raw_connection
    return self._wrap_pool_connect(self.pool.connect, _connection)
  File "/home/airflow/.local/lib/python3.7/site-packages/sqlalchemy/engine/base.py", line 3243, in _wrap_pool_connect
    return fn()
  File "/home/airflow/.local/lib/python3.7/site-packages/sqlalchemy/pool/base.py", line 310, in connect
    return _ConnectionFairy._checkout(self)
  File "/home/airflow/.local/lib/python3.7/site-packages/sqlalchemy/pool/base.py", line 868, in _checkout
    fairy = _ConnectionRecord.checkout(pool)
  File "/home/airflow/.local/lib/python3.7/site-packages/sqlalchemy/pool/base.py", line 476, in checkout
    rec = pool._do_get()
  File "/home/airflow/.local/lib/python3.7/site-packages/sqlalchemy/pool/impl.py", line 146, in _do_get
    self._dec_overflow()
  File "/home/airflow/.local/lib/python3.7/site-packages/sqlalchemy/util/langhelpers.py", line 72, in __exit__
    with_traceback=exc_tb,
  File "/home/airflow/.local/lib/python3.7/site-packages/sqlalchemy/util/compat.py", line 207, in raise_
    raise exception
  File "/home/airflow/.local/lib/python3.7/site-packages/sqlalchemy/pool/impl.py", line 143, in _do_get
    return self._create_connection()
  File "/home/airflow/.local/lib/python3.7/site-packages/sqlalchemy/pool/base.py", line 256, in _create_connection
    return _ConnectionRecord(self)
  File "/home/airflow/.local/lib/python3.7/site-packages/sqlalchemy/pool/base.py", line 371, in __init__
    self.__connect()
  File "/home/airflow/.local/lib/python3.7/site-packages/sqlalchemy/pool/base.py", line 679, in __connect
    )._exec_w_sync_on_first_run(self.dbapi_connection, self)
  File "/home/airflow/.local/lib/python3.7/site-packages/sqlalchemy/event/attr.py", line 329, in _exec_w_sync_on_first_run
    self(*args, **kw)
  File "/home/airflow/.local/lib/python3.7/site-packages/sqlalchemy/event/attr.py", line 343, in __call__
    fn(*args, **kw)
  File "/home/airflow/.local/lib/python3.7/site-packages/sqlalchemy/util/langhelpers.py", line 1691, in go
    return once_fn(*arg, **kw)
  File "/home/airflow/.local/lib/python3.7/site-packages/sqlalchemy/engine/create.py", line 686, in first_connect
    dialect.initialize(c)
  File "/home/airflow/.local/lib/python3.7/site-packages/sqlalchemy/dialects/postgresql/psycopg2.py", line 764, in initialize
    super(PGDialect_psycopg2, self).initialize(connection)
  File "/home/airflow/.local/lib/python3.7/site-packages/sqlalchemy/dialects/postgresql/base.py", line 3224, in initialize
    super(PGDialect, self).initialize(connection)
  File "/home/airflow/.local/lib/python3.7/site-packages/sqlalchemy/engine/default.py", line 395, in initialize
    connection
  File "/home/airflow/.local/lib/python3.7/site-packages/sqlalchemy/dialects/postgresql/base.py", line 3470, in _get_server_version_info
    v = connection.exec_driver_sql("select pg_catalog.version()").scalar()
  File "/home/airflow/.local/lib/python3.7/site-packages/sqlalchemy/engine/base.py", line 1674, in exec_driver_sql
    future=True,
  File "/home/airflow/.local/lib/python3.7/site-packages/sqlalchemy/engine/base.py", line 1585, in _exec_driver_sql
    distilled_parameters,
  File "/home/airflow/.local/lib/python3.7/site-packages/sqlalchemy/engine/base.py", line 1846, in _execute_context
    e, statement, parameters, cursor, context
  File "/home/airflow/.local/lib/python3.7/site-packages/sqlalchemy/engine/base.py", line 2030, in _handle_dbapi_exception
    util.raise_(exc_info[1], with_traceback=exc_info[2])
  File "/home/airflow/.local/lib/python3.7/site-packages/sqlalchemy/util/compat.py", line 207, in raise_
    raise exception
  File "/home/airflow/.local/lib/python3.7/site-packages/sqlalchemy/engine/base.py", line 1818, in _execute_context
    result = context._setup_result_proxy()
  File "/home/airflow/.local/lib/python3.7/site-packages/sqlalchemy/engine/default.py", line 1411, in _setup_result_proxy
    result = self._setup_dml_or_text_result()
  File "/home/airflow/.local/lib/python3.7/site-packages/sqlalchemy/engine/default.py", line 1502, in _setup_dml_or_text_result
    self, strategy, cursor_description
  File "/home/airflow/.local/lib/python3.7/site-packages/sqlalchemy/engine/cursor.py", line 1264, in __init__
    metadata = self._init_metadata(context, cursor_description)
  File "/home/airflow/.local/lib/python3.7/site-packages/sqlalchemy/engine/cursor.py", line 1327, in _init_metadata
    self, cursor_description
  File "/home/airflow/.local/lib/python3.7/site-packages/sqlalchemy/engine/cursor.py", line 187, in __init__
    loose_column_name_matching,
  File "/home/airflow/.local/lib/python3.7/site-packages/sqlalchemy/engine/cursor.py", line 435, in _merge_cursor_description
    ) in raw_iterator
  File "/home/airflow/.local/lib/python3.7/site-packages/sqlalchemy/engine/cursor.py", line 434, in <listcomp>
    untranslated,
  File "/home/airflow/.local/lib/python3.7/site-packages/sqlalchemy/engine/default.py", line 1375, in get_result_processor
    return type_._cached_result_processor(self.dialect, coltype)
  File "/home/airflow/.local/lib/python3.7/site-packages/sqlalchemy/sql/type_api.py", line 687, in _cached_result_processor
    d = self._dialect_info(dialect)
  File "/home/airflow/.local/lib/python3.7/site-packages/sqlalchemy/sql/type_api.py", line 714, in _dialect_info
    impl = self._gen_dialect_impl(dialect)
  File "/home/airflow/.local/lib/python3.7/site-packages/sqlalchemy/sql/type_api.py", line 723, in _gen_dialect_impl
    return dialect.type_descriptor(self)
  File "/home/airflow/.local/lib/python3.7/site-packages/sqlalchemy/engine/default.py", line 564, in type_descriptor
    return sqltypes.adapt_type(typeobj, self.colspecs)
  File "/home/airflow/.local/lib/python3.7/site-packages/sqlalchemy/sql/type_api.py", line 1782, in adapt_type
    def adapt_type(typeobj, colspecs):
  File "/home/airflow/.local/lib/python3.7/site-packages/airflow/models/taskinstance.py", line 1555, in signal_handler
    raise AirflowException("Task received SIGTERM signal")
airflow.exceptions.AirflowException: Task received SIGTERM signal
[2025-08-29T18:51:16.074+0000] {taskinstance.py:1412} INFO - Marking task as FAILED. dag_id=etl_P2M3_muhammad_al_ghifari, task_id=extract, execution_date=20250719T022000, start_date=20250829T185030, end_date=20250829T185116
[2025-08-29T18:51:16.274+0000] {standard_task_runner.py:97} ERROR - Failed to execute job 246 for task extract (Task received SIGTERM signal; 446)
[2025-08-29T18:51:16.395+0000] {process_utils.py:75} INFO - Process psutil.Process(pid=446, status='terminated', exitcode=1, started='18:50:34') (446) terminated with exit code 1
[2025-08-29T18:51:16.494+0000] {local_task_job.py:156} INFO - Task exited with return code 143
[2025-08-29T18:51:17.333+0000] {local_task_job.py:279} INFO - 0 downstream tasks scheduled from follow-on schedule check
