[2025-08-29T18:50:30.900+0000] {taskinstance.py:1171} INFO - Dependencies all met for <TaskInstance: etl_P2M3_muhammad_al_ghifari.preprocess_data scheduled__2025-06-21T02:30:00+00:00 [queued]>
[2025-08-29T18:50:32.570+0000] {taskinstance.py:1171} INFO - Dependencies all met for <TaskInstance: etl_P2M3_muhammad_al_ghifari.preprocess_data scheduled__2025-06-21T02:30:00+00:00 [queued]>
[2025-08-29T18:50:32.607+0000] {taskinstance.py:1368} INFO - 
--------------------------------------------------------------------------------
[2025-08-29T18:50:32.613+0000] {taskinstance.py:1369} INFO - Starting attempt 1 of 1
[2025-08-29T18:50:32.620+0000] {taskinstance.py:1370} INFO - 
--------------------------------------------------------------------------------
[2025-08-29T18:50:33.487+0000] {taskinstance.py:1389} INFO - Executing <Task(_PythonDecoratedOperator): preprocess_data> on 2025-06-21 02:30:00+00:00
[2025-08-29T18:50:34.236+0000] {standard_task_runner.py:52} INFO - Started process 443 to run task
[2025-08-29T18:50:34.364+0000] {standard_task_runner.py:79} INFO - Running: ['***', 'tasks', 'run', 'etl_P2M3_muhammad_al_ghifari', 'preprocess_data', 'scheduled__2025-06-21T02:30:00+00:00', '--job-id', '247', '--raw', '--subdir', 'DAGS_FOLDER/P2M3_muhammad_al_ghifari_DAG.py', '--cfg-path', '/tmp/tmp2lkk8o_4', '--error-file', '/tmp/tmpwkyzwem7']
[2025-08-29T18:50:34.424+0000] {standard_task_runner.py:80} INFO - Job 247: Subtask preprocess_data
[2025-08-29T18:50:54.304+0000] {task_command.py:371} INFO - Running <TaskInstance: etl_P2M3_muhammad_al_ghifari.preprocess_data scheduled__2025-06-21T02:30:00+00:00 [running]> on host b40c5a90b1e4
[2025-08-29T18:51:13.140+0000] {local_task_job.py:84} ERROR - Received SIGTERM. Terminating subprocesses
[2025-08-29T18:51:14.169+0000] {process_utils.py:129} INFO - Sending Signals.SIGTERM to group 443. PIDs of all processes in the group: [443]
[2025-08-29T18:51:14.195+0000] {process_utils.py:80} INFO - Sending the signal Signals.SIGTERM to group 443
[2025-08-29T18:51:14.444+0000] {taskinstance.py:1553} ERROR - Received SIGTERM. Terminating subprocesses.
[2025-08-29T18:51:14.990+0000] {taskinstance.py:1902} ERROR - Task failed with exception
Traceback (most recent call last):
  File "/home/airflow/.local/lib/python3.7/site-packages/airflow/models/taskinstance.py", line 1463, in _run_raw_task
    self._execute_task_with_callbacks(context, test_mode)
  File "/home/airflow/.local/lib/python3.7/site-packages/airflow/models/taskinstance.py", line 1567, in _execute_task_with_callbacks
    task_orig = self.render_templates(context=context)
  File "/home/airflow/.local/lib/python3.7/site-packages/airflow/models/taskinstance.py", line 2225, in render_templates
    rendered_task = self.task.render_template_fields(context)
  File "/home/airflow/.local/lib/python3.7/site-packages/airflow/models/baseoperator.py", line 1187, in render_template_fields
    jinja_env = self.get_template_env()
  File "/home/airflow/.local/lib/python3.7/site-packages/airflow/models/abstractoperator.py", line 154, in get_template_env
    return dag.get_template_env(force_sandboxed=False)
  File "/home/airflow/.local/lib/python3.7/site-packages/airflow/models/dag.py", line 1325, in get_template_env
    env = airflow.templates.SandboxedEnvironment(**jinja_env_options)
  File "/home/airflow/.local/lib/python3.7/site-packages/airflow/templates.py", line 29, in __init__
    super().__init__(**kwargs)
  File "/home/airflow/.local/lib/python3.7/site-packages/jinja2/sandbox.py", line 253, in __init__
    super().__init__(*args, **kwargs)
  File "/home/airflow/.local/lib/python3.7/site-packages/jinja2/environment.py", line 363, in __init__
    self.extensions = load_extensions(self, extensions)
  File "/home/airflow/.local/lib/python3.7/site-packages/jinja2/environment.py", line 117, in load_extensions
    extension = t.cast(t.Type["Extension"], import_string(extension))
  File "/home/airflow/.local/lib/python3.7/site-packages/jinja2/utils.py", line 149, in import_string
    return getattr(__import__(module, None, None, [obj]), obj)
  File "<frozen importlib._bootstrap>", line 983, in _find_and_load
  File "<frozen importlib._bootstrap>", line 967, in _find_and_load_unlocked
  File "<frozen importlib._bootstrap>", line 677, in _load_unlocked
  File "<frozen importlib._bootstrap_external>", line 724, in exec_module
  File "<frozen importlib._bootstrap_external>", line 857, in get_code
  File "<frozen importlib._bootstrap_external>", line 525, in _compile_bytecode
  File "/home/airflow/.local/lib/python3.7/site-packages/airflow/models/taskinstance.py", line 1555, in signal_handler
    raise AirflowException("Task received SIGTERM signal")
airflow.exceptions.AirflowException: Task received SIGTERM signal
[2025-08-29T18:51:15.325+0000] {taskinstance.py:1412} INFO - Marking task as FAILED. dag_id=etl_P2M3_muhammad_al_ghifari, task_id=preprocess_data, execution_date=20250621T023000, start_date=20250829T185030, end_date=20250829T185115
[2025-08-29T18:51:15.810+0000] {standard_task_runner.py:97} ERROR - Failed to execute job 247 for task preprocess_data (Task received SIGTERM signal; 443)
[2025-08-29T18:51:16.062+0000] {process_utils.py:75} INFO - Process psutil.Process(pid=443, status='terminated', exitcode=1, started='18:50:33') (443) terminated with exit code 1
[2025-08-29T18:51:16.121+0000] {local_task_job.py:156} INFO - Task exited with return code 143
[2025-08-29T18:51:17.138+0000] {local_task_job.py:279} INFO - 0 downstream tasks scheduled from follow-on schedule check
