[2025-08-29T19:03:31.917+0000] {taskinstance.py:1171} INFO - Dependencies all met for <TaskInstance: etl_P2M3_muhammad_al_ghifari.extract scheduled__2025-08-23T02:10:00+00:00 [queued]>
[2025-08-29T19:03:32.192+0000] {taskinstance.py:1171} INFO - Dependencies all met for <TaskInstance: etl_P2M3_muhammad_al_ghifari.extract scheduled__2025-08-23T02:10:00+00:00 [queued]>
[2025-08-29T19:03:32.195+0000] {taskinstance.py:1368} INFO - 
--------------------------------------------------------------------------------
[2025-08-29T19:03:32.198+0000] {taskinstance.py:1369} INFO - Starting attempt 1 of 1
[2025-08-29T19:03:32.198+0000] {taskinstance.py:1370} INFO - 
--------------------------------------------------------------------------------
[2025-08-29T19:03:32.521+0000] {taskinstance.py:1389} INFO - Executing <Task(_PythonDecoratedOperator): extract> on 2025-08-23 02:10:00+00:00
[2025-08-29T19:03:32.779+0000] {standard_task_runner.py:52} INFO - Started process 270 to run task
[2025-08-29T19:03:32.834+0000] {standard_task_runner.py:79} INFO - Running: ['***', 'tasks', 'run', 'etl_P2M3_muhammad_al_ghifari', 'extract', 'scheduled__2025-08-23T02:10:00+00:00', '--job-id', '268', '--raw', '--subdir', 'DAGS_FOLDER/P2M3_muhammad_al_ghifari_DAG.py', '--cfg-path', '/tmp/tmpqx4afsq2', '--error-file', '/tmp/tmppiam84z3']
[2025-08-29T19:03:32.861+0000] {standard_task_runner.py:80} INFO - Job 268: Subtask extract
[2025-08-29T19:03:35.681+0000] {task_command.py:371} INFO - Running <TaskInstance: etl_P2M3_muhammad_al_ghifari.extract scheduled__2025-08-23T02:10:00+00:00 [running]> on host dfc6b3a208a1
[2025-08-29T19:03:41.482+0000] {taskinstance.py:1583} INFO - Exporting the following env vars:
AIRFLOW_CTX_DAG_OWNER=Muhammad Al Ghifari
AIRFLOW_CTX_DAG_ID=etl_P2M3_muhammad_al_ghifari
AIRFLOW_CTX_TASK_ID=extract
AIRFLOW_CTX_EXECUTION_DATE=2025-08-23T02:10:00+00:00
AIRFLOW_CTX_TRY_NUMBER=1
AIRFLOW_CTX_DAG_RUN_ID=scheduled__2025-08-23T02:10:00+00:00
[2025-08-29T19:03:42.513+0000] {logging_mixin.py:115} INFO - Success INSERT
[2025-08-29T19:03:42.592+0000] {python.py:173} INFO - Done. Returned value was: None
[2025-08-29T19:03:43.244+0000] {local_task_job.py:84} ERROR - Received SIGTERM. Terminating subprocesses
[2025-08-29T19:03:43.373+0000] {process_utils.py:129} INFO - Sending Signals.SIGTERM to group 270. PIDs of all processes in the group: [270]
[2025-08-29T19:03:43.427+0000] {process_utils.py:80} INFO - Sending the signal Signals.SIGTERM to group 270
[2025-08-29T19:03:48.566+0000] {taskinstance.py:1553} ERROR - Received SIGTERM. Terminating subprocesses.
[2025-08-29T19:03:48.738+0000] {taskinstance.py:1902} ERROR - Task failed with exception
Traceback (most recent call last):
  File "/home/airflow/.local/lib/python3.7/site-packages/airflow/models/taskinstance.py", line 1465, in _run_raw_task
    self.refresh_from_db(lock_for_update=True, session=session)
  File "/home/airflow/.local/lib/python3.7/site-packages/airflow/utils/session.py", line 68, in wrapper
    return func(*args, **kwargs)
  File "/home/airflow/.local/lib/python3.7/site-packages/airflow/models/taskinstance.py", line 881, in refresh_from_db
    for attempt in run_with_db_retries(logger=self.log):
  File "/home/airflow/.local/lib/python3.7/site-packages/tenacity/__init__.py", line 382, in __iter__
    do = self.iter(retry_state=retry_state)
  File "/home/airflow/.local/lib/python3.7/site-packages/tenacity/__init__.py", line 349, in iter
    return fut.result()
  File "/usr/local/lib/python3.7/concurrent/futures/_base.py", line 428, in result
    return self.__get_result()
  File "/usr/local/lib/python3.7/concurrent/futures/_base.py", line 384, in __get_result
    raise self._exception
  File "/home/airflow/.local/lib/python3.7/site-packages/airflow/models/taskinstance.py", line 883, in refresh_from_db
    ti: Optional[TaskInstance] = qry.with_for_update().first()
  File "/home/airflow/.local/lib/python3.7/site-packages/sqlalchemy/orm/query.py", line 2810, in first
    return self.limit(1)._iter().first()
  File "/home/airflow/.local/lib/python3.7/site-packages/sqlalchemy/orm/query.py", line 2897, in _iter
    execution_options={"_sa_orm_load_options": self.load_options},
  File "/home/airflow/.local/lib/python3.7/site-packages/sqlalchemy/orm/session.py", line 1689, in execute
    result = conn._execute_20(statement, params or {}, execution_options)
  File "/home/airflow/.local/lib/python3.7/site-packages/sqlalchemy/engine/base.py", line 1614, in _execute_20
    return meth(self, args_10style, kwargs_10style, execution_options)
  File "/home/airflow/.local/lib/python3.7/site-packages/sqlalchemy/sql/elements.py", line 326, in _execute_on_connection
    self, multiparams, params, execution_options
  File "/home/airflow/.local/lib/python3.7/site-packages/sqlalchemy/engine/base.py", line 1491, in _execute_clauseelement
    cache_hit=cache_hit,
  File "/home/airflow/.local/lib/python3.7/site-packages/sqlalchemy/engine/base.py", line 1846, in _execute_context
    e, statement, parameters, cursor, context
  File "/home/airflow/.local/lib/python3.7/site-packages/sqlalchemy/engine/base.py", line 2030, in _handle_dbapi_exception
    util.raise_(exc_info[1], with_traceback=exc_info[2])
  File "/home/airflow/.local/lib/python3.7/site-packages/sqlalchemy/util/compat.py", line 207, in raise_
    raise exception
  File "/home/airflow/.local/lib/python3.7/site-packages/sqlalchemy/engine/base.py", line 1803, in _execute_context
    cursor, statement, parameters, context
  File "/home/airflow/.local/lib/python3.7/site-packages/sqlalchemy/engine/default.py", line 719, in do_execute
    cursor.execute(statement, parameters)
  File "/usr/local/lib/python3.7/encodings/utf_8.py", line 15, in decode
    def decode(input, errors='strict'):
  File "/home/airflow/.local/lib/python3.7/site-packages/airflow/models/taskinstance.py", line 1555, in signal_handler
    raise AirflowException("Task received SIGTERM signal")
airflow.exceptions.AirflowException: Task received SIGTERM signal
[2025-08-29T19:03:48.867+0000] {taskinstance.py:1412} INFO - Marking task as FAILED. dag_id=etl_P2M3_muhammad_al_ghifari, task_id=extract, execution_date=20250823T021000, start_date=20250829T190331, end_date=20250829T190348
[2025-08-29T19:03:48.989+0000] {standard_task_runner.py:97} ERROR - Failed to execute job 268 for task extract (Task received SIGTERM signal; 270)
[2025-08-29T19:03:49.113+0000] {process_utils.py:75} INFO - Process psutil.Process(pid=270, status='terminated', exitcode=1, started='19:03:32') (270) terminated with exit code 1
[2025-08-29T19:03:49.129+0000] {local_task_job.py:156} INFO - Task exited with return code 143
[2025-08-29T19:03:50.259+0000] {local_task_job.py:279} INFO - 0 downstream tasks scheduled from follow-on schedule check
