[2025-08-29T18:46:49.485+0000] {taskinstance.py:1171} INFO - Dependencies all met for <TaskInstance: etl_P2M3_muhammad_al_ghifari.load scheduled__2025-04-26T02:10:00+00:00 [queued]>
[2025-08-29T18:46:49.689+0000] {taskinstance.py:1171} INFO - Dependencies all met for <TaskInstance: etl_P2M3_muhammad_al_ghifari.load scheduled__2025-04-26T02:10:00+00:00 [queued]>
[2025-08-29T18:46:49.694+0000] {taskinstance.py:1368} INFO - 
--------------------------------------------------------------------------------
[2025-08-29T18:46:49.697+0000] {taskinstance.py:1369} INFO - Starting attempt 1 of 1
[2025-08-29T18:46:49.701+0000] {taskinstance.py:1370} INFO - 
--------------------------------------------------------------------------------
[2025-08-29T18:46:50.121+0000] {taskinstance.py:1389} INFO - Executing <Task(_PythonDecoratedOperator): load> on 2025-04-26 02:10:00+00:00
[2025-08-29T18:46:50.358+0000] {standard_task_runner.py:52} INFO - Started process 235 to run task
[2025-08-29T18:46:50.556+0000] {standard_task_runner.py:79} INFO - Running: ['***', 'tasks', 'run', 'etl_P2M3_muhammad_al_ghifari', 'load', 'scheduled__2025-04-26T02:10:00+00:00', '--job-id', '188', '--raw', '--subdir', 'DAGS_FOLDER/P2M3_muhammad_al_ghifari_DAG.py', '--cfg-path', '/tmp/tmpaexfr9s_', '--error-file', '/tmp/tmph9wbmbul']
[2025-08-29T18:46:50.876+0000] {standard_task_runner.py:80} INFO - Job 188: Subtask load
[2025-08-29T18:46:54.463+0000] {task_command.py:371} INFO - Running <TaskInstance: etl_P2M3_muhammad_al_ghifari.load scheduled__2025-04-26T02:10:00+00:00 [running]> on host b40c5a90b1e4
[2025-08-29T18:46:55.754+0000] {taskinstance.py:1583} INFO - Exporting the following env vars:
AIRFLOW_CTX_DAG_OWNER=Muhammad Al Ghifari
AIRFLOW_CTX_DAG_ID=etl_P2M3_muhammad_al_ghifari
AIRFLOW_CTX_TASK_ID=load
AIRFLOW_CTX_EXECUTION_DATE=2025-04-26T02:10:00+00:00
AIRFLOW_CTX_TRY_NUMBER=1
AIRFLOW_CTX_DAG_RUN_ID=scheduled__2025-04-26T02:10:00+00:00
[2025-08-29T18:46:56.155+0000] {base.py:271} INFO - HEAD http://elasticsearch:9200/ [status:200 request:0.132s]
[2025-08-29T18:46:56.157+0000] {logging_mixin.py:115} INFO - True
[2025-08-29T18:47:06.813+0000] {base.py:299} WARNING - POST http://elasticsearch:9200/logistics_project/doc [status:N/A request:10.128s]
Traceback (most recent call last):
  File "/home/airflow/.local/lib/python3.7/site-packages/urllib3/connectionpool.py", line 449, in _make_request
    six.raise_from(e, None)
  File "<string>", line 3, in raise_from
  File "/home/airflow/.local/lib/python3.7/site-packages/urllib3/connectionpool.py", line 444, in _make_request
    httplib_response = conn.getresponse()
  File "/usr/local/lib/python3.7/http/client.py", line 1373, in getresponse
    response.begin()
  File "/usr/local/lib/python3.7/http/client.py", line 319, in begin
    version, status, reason = self._read_status()
  File "/usr/local/lib/python3.7/http/client.py", line 280, in _read_status
    line = str(self.fp.readline(_MAXLINE + 1), "iso-8859-1")
  File "/usr/local/lib/python3.7/socket.py", line 589, in readinto
    return self._sock.recv_into(b)
socket.timeout: timed out

During handling of the above exception, another exception occurred:

Traceback (most recent call last):
  File "/home/airflow/.local/lib/python3.7/site-packages/elasticsearch/connection/http_urllib3.py", line 252, in perform_request
    method, url, body, retries=Retry(False), headers=request_headers, **kw
  File "/home/airflow/.local/lib/python3.7/site-packages/urllib3/connectionpool.py", line 788, in urlopen
    method, url, error=e, _pool=self, _stacktrace=sys.exc_info()[2]
  File "/home/airflow/.local/lib/python3.7/site-packages/urllib3/util/retry.py", line 525, in increment
    raise six.reraise(type(error), error, _stacktrace)
  File "/home/airflow/.local/lib/python3.7/site-packages/urllib3/packages/six.py", line 770, in reraise
    raise value
  File "/home/airflow/.local/lib/python3.7/site-packages/urllib3/connectionpool.py", line 710, in urlopen
    chunked=chunked,
  File "/home/airflow/.local/lib/python3.7/site-packages/urllib3/connectionpool.py", line 451, in _make_request
    self._raise_timeout(err=e, url=url, timeout_value=read_timeout)
  File "/home/airflow/.local/lib/python3.7/site-packages/urllib3/connectionpool.py", line 341, in _raise_timeout
    self, url, "Read timed out. (read timeout=%s)" % timeout_value
urllib3.exceptions.ReadTimeoutError: HTTPConnectionPool(host='elasticsearch', port=9200): Read timed out. (read timeout=10)
[2025-08-29T18:47:07.189+0000] {taskinstance.py:1902} ERROR - Task failed with exception
Traceback (most recent call last):
  File "/home/airflow/.local/lib/python3.7/site-packages/urllib3/connectionpool.py", line 449, in _make_request
    six.raise_from(e, None)
  File "<string>", line 3, in raise_from
  File "/home/airflow/.local/lib/python3.7/site-packages/urllib3/connectionpool.py", line 444, in _make_request
    httplib_response = conn.getresponse()
  File "/usr/local/lib/python3.7/http/client.py", line 1373, in getresponse
    response.begin()
  File "/usr/local/lib/python3.7/http/client.py", line 319, in begin
    version, status, reason = self._read_status()
  File "/usr/local/lib/python3.7/http/client.py", line 280, in _read_status
    line = str(self.fp.readline(_MAXLINE + 1), "iso-8859-1")
  File "/usr/local/lib/python3.7/socket.py", line 589, in readinto
    return self._sock.recv_into(b)
socket.timeout: timed out

During handling of the above exception, another exception occurred:

Traceback (most recent call last):
  File "/home/airflow/.local/lib/python3.7/site-packages/elasticsearch/connection/http_urllib3.py", line 252, in perform_request
    method, url, body, retries=Retry(False), headers=request_headers, **kw
  File "/home/airflow/.local/lib/python3.7/site-packages/urllib3/connectionpool.py", line 788, in urlopen
    method, url, error=e, _pool=self, _stacktrace=sys.exc_info()[2]
  File "/home/airflow/.local/lib/python3.7/site-packages/urllib3/util/retry.py", line 525, in increment
    raise six.reraise(type(error), error, _stacktrace)
  File "/home/airflow/.local/lib/python3.7/site-packages/urllib3/packages/six.py", line 770, in reraise
    raise value
  File "/home/airflow/.local/lib/python3.7/site-packages/urllib3/connectionpool.py", line 710, in urlopen
    chunked=chunked,
  File "/home/airflow/.local/lib/python3.7/site-packages/urllib3/connectionpool.py", line 451, in _make_request
    self._raise_timeout(err=e, url=url, timeout_value=read_timeout)
  File "/home/airflow/.local/lib/python3.7/site-packages/urllib3/connectionpool.py", line 341, in _raise_timeout
    self, url, "Read timed out. (read timeout=%s)" % timeout_value
urllib3.exceptions.ReadTimeoutError: HTTPConnectionPool(host='elasticsearch', port=9200): Read timed out. (read timeout=10)

During handling of the above exception, another exception occurred:

Traceback (most recent call last):
  File "/home/airflow/.local/lib/python3.7/site-packages/airflow/decorators/base.py", line 179, in execute
    return_value = super().execute(context)
  File "/home/airflow/.local/lib/python3.7/site-packages/airflow/operators/python.py", line 171, in execute
    return_value = self.execute_callable()
  File "/home/airflow/.local/lib/python3.7/site-packages/airflow/operators/python.py", line 189, in execute_callable
    return self.python_callable(*self.op_args, **self.op_kwargs)
  File "/opt/airflow/dags/P2M3_muhammad_al_ghifari_DAG.py", line 174, in load
    res=es.index(index="logistics_project", doc_type="doc", body=row.to_json())
  File "/home/airflow/.local/lib/python3.7/site-packages/elasticsearch/client/utils.py", line 168, in _wrapped
    return func(*args, params=params, headers=headers, **kwargs)
  File "/home/airflow/.local/lib/python3.7/site-packages/elasticsearch/client/__init__.py", line 411, in index
    body=body,
  File "/home/airflow/.local/lib/python3.7/site-packages/elasticsearch/transport.py", line 415, in perform_request
    raise e
  File "/home/airflow/.local/lib/python3.7/site-packages/elasticsearch/transport.py", line 388, in perform_request
    timeout=timeout,
  File "/home/airflow/.local/lib/python3.7/site-packages/elasticsearch/connection/http_urllib3.py", line 265, in perform_request
    raise ConnectionTimeout("TIMEOUT", str(e), e)
elasticsearch.exceptions.ConnectionTimeout: ConnectionTimeout caused by - ReadTimeoutError(HTTPConnectionPool(host='elasticsearch', port=9200): Read timed out. (read timeout=10))
[2025-08-29T18:47:07.701+0000] {taskinstance.py:1412} INFO - Marking task as FAILED. dag_id=etl_P2M3_muhammad_al_ghifari, task_id=load, execution_date=20250426T021000, start_date=20250829T184649, end_date=20250829T184707
[2025-08-29T18:47:08.294+0000] {standard_task_runner.py:97} ERROR - Failed to execute job 188 for task load (ConnectionTimeout caused by - ReadTimeoutError(HTTPConnectionPool(host='elasticsearch', port=9200): Read timed out. (read timeout=10)); 235)
[2025-08-29T18:47:08.661+0000] {local_task_job.py:156} INFO - Task exited with return code 1
[2025-08-29T18:47:09.606+0000] {local_task_job.py:279} INFO - 0 downstream tasks scheduled from follow-on schedule check
