[2025-08-30T11:40:04.027+0000] {taskinstance.py:1171} INFO - Dependencies all met for <TaskInstance: etl_P2M3_muhammad_al_ghifari.preprocess_data manual__2025-08-30T11:39:59.825010+00:00 [queued]>
[2025-08-30T11:40:04.033+0000] {taskinstance.py:1171} INFO - Dependencies all met for <TaskInstance: etl_P2M3_muhammad_al_ghifari.preprocess_data manual__2025-08-30T11:39:59.825010+00:00 [queued]>
[2025-08-30T11:40:04.033+0000] {taskinstance.py:1368} INFO - 
--------------------------------------------------------------------------------
[2025-08-30T11:40:04.033+0000] {taskinstance.py:1369} INFO - Starting attempt 1 of 1
[2025-08-30T11:40:04.033+0000] {taskinstance.py:1370} INFO - 
--------------------------------------------------------------------------------
[2025-08-30T11:40:04.044+0000] {taskinstance.py:1389} INFO - Executing <Task(_PythonDecoratedOperator): preprocess_data> on 2025-08-30 11:39:59.825010+00:00
[2025-08-30T11:40:04.054+0000] {standard_task_runner.py:52} INFO - Started process 198 to run task
[2025-08-30T11:40:04.058+0000] {standard_task_runner.py:79} INFO - Running: ['***', 'tasks', 'run', 'etl_P2M3_muhammad_al_ghifari', 'preprocess_data', 'manual__2025-08-30T11:39:59.825010+00:00', '--job-id', '303', '--raw', '--subdir', 'DAGS_FOLDER/P2M3_muhammad_al_ghifari_DAG.py', '--cfg-path', '/tmp/tmp2w19qycq', '--error-file', '/tmp/tmp5tvicy2q']
[2025-08-30T11:40:04.060+0000] {standard_task_runner.py:80} INFO - Job 303: Subtask preprocess_data
[2025-08-30T11:40:04.135+0000] {task_command.py:371} INFO - Running <TaskInstance: etl_P2M3_muhammad_al_ghifari.preprocess_data manual__2025-08-30T11:39:59.825010+00:00 [running]> on host e16607c3436f
[2025-08-30T11:40:04.205+0000] {taskinstance.py:1583} INFO - Exporting the following env vars:
AIRFLOW_CTX_DAG_OWNER=Muhammad Al Ghifari
AIRFLOW_CTX_DAG_ID=etl_P2M3_muhammad_al_ghifari
AIRFLOW_CTX_TASK_ID=preprocess_data
AIRFLOW_CTX_EXECUTION_DATE=2025-08-30T11:39:59.825010+00:00
AIRFLOW_CTX_TRY_NUMBER=1
AIRFLOW_CTX_DAG_RUN_ID=manual__2025-08-30T11:39:59.825010+00:00
[2025-08-30T11:40:04.249+0000] {taskinstance.py:1902} ERROR - Task failed with exception
Traceback (most recent call last):
  File "/home/airflow/.local/lib/python3.7/site-packages/airflow/decorators/base.py", line 179, in execute
    return_value = super().execute(context)
  File "/home/airflow/.local/lib/python3.7/site-packages/airflow/operators/python.py", line 171, in execute
    return_value = self.execute_callable()
  File "/home/airflow/.local/lib/python3.7/site-packages/airflow/operators/python.py", line 189, in execute_callable
    return self.python_callable(*self.op_args, **self.op_kwargs)
  File "/opt/airflow/dags/P2M3_muhammad_al_ghifari_DAG.py", line 154, in preprocess_data
    df['rate'] = df['cost'] / (df['weight_kg'] * df['distance_miles'])
  File "/home/airflow/.local/lib/python3.7/site-packages/pandas/core/ops/common.py", line 69, in new_method
    return method(self, other)
  File "/home/airflow/.local/lib/python3.7/site-packages/pandas/core/arraylike.py", line 116, in __truediv__
    return self._arith_method(other, operator.truediv)
  File "/home/airflow/.local/lib/python3.7/site-packages/pandas/core/series.py", line 5526, in _arith_method
    result = ops.arithmetic_op(lvalues, rvalues, op)
  File "/home/airflow/.local/lib/python3.7/site-packages/pandas/core/ops/array_ops.py", line 224, in arithmetic_op
    res_values = _na_arithmetic_op(left, right, op)
  File "/home/airflow/.local/lib/python3.7/site-packages/pandas/core/ops/array_ops.py", line 166, in _na_arithmetic_op
    result = func(left, right)
  File "/home/airflow/.local/lib/python3.7/site-packages/pandas/core/computation/expressions.py", line 239, in evaluate
    return _evaluate(op, op_str, a, b)  # type: ignore[misc]
  File "/home/airflow/.local/lib/python3.7/site-packages/pandas/core/computation/expressions.py", line 69, in _evaluate_standard
    return op(a, b)
ZeroDivisionError: float division by zero
[2025-08-30T11:40:04.263+0000] {taskinstance.py:1412} INFO - Marking task as FAILED. dag_id=etl_P2M3_muhammad_al_ghifari, task_id=preprocess_data, execution_date=20250830T113959, start_date=20250830T114004, end_date=20250830T114004
[2025-08-30T11:40:04.270+0000] {standard_task_runner.py:97} ERROR - Failed to execute job 303 for task preprocess_data (float division by zero; 198)
[2025-08-30T11:40:04.278+0000] {local_task_job.py:156} INFO - Task exited with return code 1
[2025-08-30T11:40:04.307+0000] {local_task_job.py:279} INFO - 0 downstream tasks scheduled from follow-on schedule check
